Workbook

Sheet BD_DESV
A1: FECHA | B1: PLACA | C1: EMPRESA | D1: NIT | E1: DIRECCIÓN | F1: PROPIETARIO | G1: CEDULA | H1: DIRECCIÓN | I1: RAD PADRE | J1: FECHA RAD- | K1: RESOLUCÓN DESVINCULACIÓN | L1: FECHA DESVINCULACIÓN | M1: OBSERVACIÓN | N1: FUNCIONARIO QUE DESVINCULA | O1: NUEVA EMPRESA | P1: SOLICITANTE | Q1: ESTADO | R1: CORREO ELECTRÓNICO | S1: RECURSO | T1: FECHA RECURSO | U1: OBSERVACIONES
A2: 45306 | B2: VBU725 | C2: COOPERATIVA ESPECIALIZADA DE TRANSPORTE Y SERVICIOS LA ERMITA LTDA. | D2: 890303525 | E2: CALLE 31 # 2BN-106 | F2: ALBA MARINA GOMEZ TORRES | G2: 66700738 | H2: CALLE 11 No. 51-30 | I2: 202441520100144132 | J2: 45644 | K2: 4152.010.21.0.12133 | L2: 45916 | M2: Si se concede | N2: PAOLA ANDREA MATAMOROS | O2: NINGUNA | P2: EMPRESA | Q2: NOTIFICACIÓN DE RESOLUCIÓN
A3: 45306 | B3: VCW646 | C3: RADIO TAXI AEROPUERTO S.A. | D3: 860531135 | E3: CALLE 52 # 1B-160 | F3: ELIZABETH CORTES | G3: 31960535 | H3: heliana999@hotmail.com | I3: 202441730102611572 | J3: 45652 | K3: 4152.010.21.0.00244 | L3: 45691 | M3: Si se concede | N3: PAOLA ANDREA MATAMOROS | O3: TAXIS VALCALI S.A. | P3: PROPIETARIO | Q3: PROCESO TERMINADO
A4: 45306 | B4: GVS650 | C4: TAXIS Y AUTOS CALI S.A.S. | D4: 805013516 | E4: AVENIDA 3N # 39N-35 | F4: LUZ AURORA SANCHEZ MORENO | G4: 66953027 | H4: CARRERA 79 A No. 32 A - 27 | I4: 202441730102621032 | J4: 45654 | K4: 4152.010.21.0.00795 | L4: 45736 | M4: Si se concede | N4: ROCIÓ RAMIREZ ACOSTA | O4: RADIO TAXI AEROPUERTO S.A. | P4: PROPIETARIO | Q4: PROCESO TERMINADO | R4: asesortramites4@carreracali.com
A5: 45435 | B5: VBO899 | C5: COOPERATIVA ESPECIALIZADA DE TRANSPORTE Y SERVICIOS LA ERMITA LTDA. | D5: 890303525 | E5: CALLE 31 # 2BN-106 | F5: EDWAR JAMES FERNANDEZ GOMEZ | G5: 94492712 | I5: 202441520100040232 | J5: 45422 | K5: 4152.010.21.0.1067 | L5: 45497 | M5: Si se concede | N5: PAOLA ANDREA MATAMOROS | O5: NINGUNA | P5: EMPRESA | Q5: PROCESO TERMINADO
A6: 45435 | B6: TZP235 | C6: TRANSPORTADORA EL PRADO LIMITADA | D6: 805010048 | E6: TRANSVERSAL 25 # 23-16 | F6: CLAUDIA PATRICIA ZULUAGA | G6: 66986088 | I6: 202441520100006602 | J6: 45309 | K6: 4152.010.21.0.0083 | L6: 45381 | M6: Si se concede | N6: PAOLA ANDREA MATAMOROS | O6: TAX EXPRESS CALI S.A.S. | P6: PROPIETARIO | Q6: PROCESO TERMINADO
A7: 45435 | B7: VCP101 | C7: TORO AUTOS S.A.S. | D7: 800007748 | E7: AVENIDA VASQUEZ COBO # 25N-68 | F7: MARCELINO GUTIERREZ GARZON | G7: 16246987 | I7: 202441730100586992 | J7: 45352 | K7: 4152.010.21.0.0282 | L7: 45383 | M7: Si se concede | N7: PAOLA ANDREA MATAMOROS | O7: COOPERATIVA MULTIACTIVA DE LOS TAXISTAS DEL AEROPUERTO DE PALMASECA LTDA COOPTAXPAL | P7: PROPIETARIO | Q7: PROCESO TERMINADO
A8: 45435 | B8: WMY186 | C8: RADIO TAXI AEROPUERTO S.A. | D8: 860531135 | E8: CALLE 52 # 1B-160 | F8: OMAIRA ELENA QUICENO | G8: 29925690 | I8: 202441730100954552 | J8: 45393 | K8: 4152.010.21.0.0430 | L8: 45406 | M8: Si se concede | N8: PAOLA ANDREA MATAMOROS | O8: COOPERATIVA MULTIACTIVA DE LOS TAXISTAS DEL AEROPUERTO DE PALMASECA LTDA COOPTAXPAL | P8: PROPIETARIO | Q8: PROCESO TERMINADO
A9: 45435 | B9: VCW476 | C9: RADIO TAXI AEROPUERTO S.A. | D9: 860531135 | E9: CALLE 52 # 1B-160 | F9: ORLANDO HIDALGO HERNANDEZ | G9: 10250005 | I9: 202441730100689452 | J9: 45363 | K9: 4152.010.21.0.0336 | L9: 45392 | M9: Si se concede | N9: PAOLA ANDREA MATAMOROS | O9: COOPERATIVA MULTIACTIVA DE LOS TAXISTAS DEL AEROPUERTO DE PALMASECA LTDA COOPTAXPAL | P9: PROPIETARIO | Q9: PROCESO TERMINADO
A10: 45435 | B10: VCD756 | C10: EMPRESA DE TRANSPORTES CAÑAVERAL S.A. | D10: 800109341 | F10: GILBERTH ANDERSON VILLAMUEZ MUÑOZ | G10: 1005865818 | H10: Carrera 42 B No. 51 - 52 | I10: 202441730100858522 | J10: 45371 | K10: 4152.010.21.0.0869 | L10: 45462 | M10: No se concede | N10: PAOLA ANDREA MATAMOROS | P10: PROPIETARIO | Q10: PROCESO TERMINADO
A11: 45435 | B11: VCI544 | C11: EMPRESA DE TRANSPORTES CAÑAVERAL S.A. | D11: 800109341 | F11: FRAN LEONARDO HERRERA ORTIZ | G11: 94520071 | H11: Carrera 42 B No. 51 - 52 | I11: 202441730100858812 | J11: 45371 | K11: 4152.010.21.0.0871 | L11: 45462 | M11: No se concede | N11: PAOLA ANDREA MATAMOROS | P11: PROPIETARIO | Q11: PROCESO TERMINADO
A12: 45435 | B12: VCC556 | C12: EMPRESA DE TRANSPORTES CAÑAVERAL S.A. | D12: 800109341 | F12: FRAN LEONARDO HERRERA ORTIZ | G12: 94520071 | H12: Carrera 42 B No. 51 - 52 | I12: 202441730100858672 | J12: 45371 | K12: 4152.010.21.0.0868 | L12: 45462 | M12: No se concede | N12: PAOLA ANDREA MATAMOROS | P12: PROPIETARIO | Q12: PROCESO TERMINADO
A13: 45435 | B13: VCT015 | C13: RADIO TAXI AEROPUERTO S.A. | D13: 860531135 | E13: CALLE 52 # 1B-160 | F13: ANGEL MARIA RAMIREZ ORJUELA | G13: 19317155 | I13: 202441520100020372 | J13: 45369 | K13: 4152.010.21.0.0329 | L13: 45391 | M13: No se concede | N13: PAOLA ANDREA MATAMOROS | O13: COOPERATIVA INTEGRAL DE TRANSPORTADORES TROPICANA LTDA. | P13: PROPIETARIO | Q13: PROCESO TERMINADO
A14: 45435 | B14: VCV376 | C14: EL MUNDO DE LOS TAXIS LTDA. | D14: 805029930 | E14: CALLE 25 N # 2 DN-07 | F14: JOSE ROBEIRO GALLEGO | G14: 75069131 | I14: 202441730100173262 | J14: 45313 | K14: 4152.010.21.0.0196 | L14: 45363 | M14: Si se concede | N14: PAOLA ANDREA MATAMOROS | O14: COOPERATIVA MULTIACTIVA DE LOS TAXISTAS DEL AEROPUERTO DE PALMASECA LTDA COOPTAXPAL | P14: PROPIETARIO | Q14: PROCESO TERMINADO
A15: 45435 | B15: VCY633 | C15: RADIO TAXI AEROPUERTO S.A. | D15: 860531135 | E15: CALLE 52 # 1B-160 | F15: ANGEL MARIA RAMIREZ ORJUELA | G15: 19317155 | I15: 202441520100017772 | J15: 45363 | K15: 4152.010.21.0.0337 | L15: 45392 | M15: Si se concede | N15: PAOLA ANDREA MATAMOROS | O15: COOPERATIVA INTEGRAL DE TRANSPORTADORES TROPICANA LTDA. | P15: PROPIETARIO | Q15: PROCESO TERMINADO
A16: 45435 | B16: VCU666 | C16: TORO AUTOS S.A.S. | D16: 800007748 | E16: AVENIDA VASQUEZ COBO # 25N-68 | F16: MILTON ARNULFO CASTRO REVELO | G16: 5348474 | I16: 202441730100172912 | J16: 45313 | K16: 4152.010.21.0.0194 | L16: 45362 | M16: Si se concede | N16: PAOLA ANDREA MATAMOROS | O16: COOPERATIVA MULTIACTIVA DE LOS TAXISTAS DEL AEROPUERTO DE PALMASECA LTDA COOPTAXPAL | P16: PROPIETARIO | Q16: PROCESO TERMINADO
A17: 45435 | B17: VCT477 | C17: TAXIS VALCALI S.A. | D17: 890308720 | E17: TRANSVERSAL 30 # 17F-174 | F17: JAIRO CERON DOMINGUEZ | G17: 16369775 | I17: 202441730100585522 | J17: 45351 | K17: 4152.010.21.0.0274 | L17: 45383 | M17: Si se concede | N17: PAOLA ANDREA MATAMOROS | O17: COOPERATIVA MULTIACTIVA DE LOS TAXISTAS DEL AEROPUERTO DE PALMASECA LTDA COOPTAXPAL | P17: PROPIETARIO | Q17: PROCESO TERMINADO
A18: 45435 | B18: VCZ834 | C18: RADIO TAXI AEROPUERTO S.A. | D18: 860531135 | E18: CALLE 52 # 1B-160 | F18: WILLIAM PECHENE VICTORIA | G18: 16638929 | I18: 202441730100587952 | J18: 45352 | K18: 4152.010.21.0.0275 | L18: 45383 | M18: Si se concede | N18: PAOLA ANDREA MATAMOROS | O18: COOPERATIVA MULTIACTIVA DE LOS TAXISTAS DEL AEROPUERTO DE PALMASECA LTDA COOPTAXPAL | P18: PROPIETARIO | Q18: PROCESO TERMINADO
A19: 45435 | B19: VCU080 | C19: RADIO TAXI AEROPUERTO S.A. | D19: 860531135 | E19: CALLE 52 # 1B-160 | F19: LUIS FERNANDO ZAMORA | G19: 16760575 | I19: 202441730100894822 | J19: 45384 | K19: 4152.010.21.0.0338 | L19: 45392 | M19: Si se concede | N19: PAOLA ANDREA MATAMOROS | O19: COOPERATIVA MULTIACTIVA DE LOS TAXISTAS DEL AEROPUERTO DE PALMASECA LTDA COOPTAXPAL | P19: PROPIETARIO | Q19: PROCESO TERMINADO
A20: 45435 | B20: VCN647 | C20: TORO AUTOS S.A.S. | D20: 800007748 | E20: AVENIDA VASQUEZ COBO # 25N-68 | F20: JORGE GENARO AREVALO CHAMORRO | G20: 98337227 | I20: 202441520100029082 | J20: 45394 | K20: 4152.010.21.0.0580 | L20: 45432 | M20: No se concede | N20: PAOLA ANDREA MATAMOROS | P20: EMPRESA | Q20: PROCESO TERMINADO
A21: 45435 | B21: VCK962 | C21: TORO AUTOS S.A.S. | D21: 800007748 | E21: AVENIDA VASQUEZ COBO # 25N-68 | F21: PERSIDES HILADELFO PRECIADO QUIÑONES | G21: 12912369 | I21: 202441520100029082 | J21: 45394 | K21: 4152.010.21.0.0581 | L21: 45432 | M21: No se concede | N21: PAOLA ANDREA MATAMOROS | O21: NINGUNA | P21: EMPRESA | Q21: PROCESO TERMINADO
A22: 45435 | B22: VCO090 | C22: TORO AUTOS S.A.S. | D22: 800007748 | E22: AVENIDA VASQUEZ COBO # 25N-68 | F22: NICOLAS VILLAMIL GARCIA | G22: 16608346 | I22: 202441520100029082 | J22: 45394 | K22: 4152.010.21.0.0578 | L22: 45432 | M22: No se concede | N22: PAOLA ANDREA MATAMOROS | O22: NINGUNA | P22: EMPRESA | Q22: PROCESO TERMINADO
A23: 45435 | B23: TZO410 | C23: TORO AUTOS S.A.S. | D23: 800007748 | E23: AVENIDA VASQUEZ COBO # 25N-68 | F23: ELKIN DARIO LONDOÑO JIMENEZ | G23: 16535263 | I23: 202441520100029082 | J23: 45394 | K23: 4152.010.21.0.0582 | L23: 45432 | M23: No se concede | N23: PAOLA ANDREA MATAMOROS | O23: NINGUNA | P23: EMPRESA | Q23: PROCESO TERMINADO
A24: 45435 | B24: VCI776 | C24: TORO AUTOS S.A.S. | D24: 800007748 | E24: AVENIDA VASQUEZ COBO # 25N-68 | F24: JUAN CARLOS CALDAS GONZALEZ | G24: 16280009 | I24: 202441520100029082 | J24: 45394 | K24: 4152.010.21.0.0579 | L24: 45432 | M24: No se concede | N24: PAOLA ANDREA MATAMOROS | O24: NINGUNA | P24: EMPRESA | Q24: PROCESO TERMINADO
A25: 45435 | B25: EQK201 | C25: TORO AUTOS S.A.S. | D25: 800007748 | E25: AVENIDA VASQUEZ COBO # 25N-68 | F25: VERONICA PEREZ RINCON | G25: 38886627 | I25: 202441520100029082 | J25: 45394 | K25: 4152.010.21.0.0585 | L25: 45432 | M25: No se concede | N25: PAOLA ANDREA MATAMOROS | O25: NINGUNA | P25: EMPRESA | Q25: PROCESO TERMINADO
A26: 45435 | B26: EQK878 | C26: TORO AUTOS S.A.S. | D26: 800007748 | E26: AVENIDA VASQUEZ COBO # 25N-68 | F26: FLOR MARIA ESTUPIÑAN MONTAÑO | G26: 66940343 | I26: 202441520100029082 | J26: 45394 | K26: 4152.010.21.0.0583 | L26: 45432 | M26: No se concede | N26: PAOLA ANDREA MATAMOROS | O26: NINGUNA | P26: EMPRESA | Q26: PROCESO TERMINADO
A27: 45435 | B27: EQK921 | C27: TORO AUTOS S.A.S. | D27: 800007748 | E27: AVENIDA VASQUEZ COBO # 25N-68 | F27: JOHANNA ORTIZ TORRES | G27: 31712908 | I27: 202441520100029082 | J27: 45394 | K27: 4152.010.21.0.0586 | L27: 45432 | M27: No se concede | N27: PAOLA ANDREA MATAMOROS | O27: NINGUNA | P27: EMPRESA | Q27: PROCESO TERMINADO
A28: 45435 | B28: VCK311 | C28: TORO AUTOS S.A.S. | D28: 800007748 | E28: AVENIDA VASQUEZ COBO # 25N-68 | F28: JESUS ANIBAL ARISTIZABAL ARISTIZABAL | G28: 94528880 | I28: 202441520100029082 | J28: 45394 | K28: 4152.010.21.0.0584 | L28: 45432 | M28: No se concede | N28: PAOLA ANDREA MATAMOROS | O28: NINGUNA | P28: EMPRESA | Q28: PROCESO TERMINADO
A29: 45435 | B29: VCM907 | C29: TORO AUTOS S.A.S. | D29: 800007748 | E29: AVENIDA VASQUEZ COBO # 25N-68 | F29: VICTOR MANUEL CASTILLO ATEHORTUA | G29: 94427599 | I29: 202441520100029082 | J29: 45394 | K29: 4152.010.21.0.0587 | L29: 45432 | M29: No se concede | N29: PAOLA ANDREA MATAMOROS | O29: NINGUNA | P29: EMPRESA | Q29: PROCESO TERMINADO
A30: 45435 | B30: WMW986 | C30: TORO AUTOS S.A.S. | D30: 800007748 | E30: AVENIDA VASQUEZ COBO # 25N-68 | F30: ALEXANDER FLOREZ BANGUERA | G30: 94504677 | I30: 202441520100029082 | J30: 45394 | K30: 4152.010.21.0.0594 | L30: 45432 | M30: No se concede | N30: PAOLA ANDREA MATAMOROS | O30: NINGUNA | P30: EMPRESA | Q30: PROCESO TERMINADO
A31: 45435 | B31: WMW914 | C31: TORO AUTOS S.A.S. | D31: 800007748 | E31: AVENIDA VASQUEZ COBO # 25N-68 | F31: SILVIA MAGALLY GONZALEZ BOLAÑOS | G31: 1107036546 | I31: 202441520100029082 | J31: 45394 | K31: 4152.010.21.0.0595 | L31: 45432 | M31: No se concede | N31: PAOLA ANDREA MATAMOROS | O31: NINGUNA | P31: EMPRESA | Q31: PROCESO TERMINADO
A32: 45435 | B32: VCS551 | C32: TORO AUTOS S.A.S. | D32: 800007748 | E32: AVENIDA VASQUEZ COBO # 25N-68 | F32: ELIZABETH GALLEGO GALVIS | G32: 38681741 | I32: 202441520100029082 | J32: 45394 | K32: 4152.010.21.0.0596 | L32: 45432 | M32: No se concede | N32: PAOLA ANDREA MATAMOROS | O32: NINGUNA | P32: EMPRESA | Q32: PROCESO TERMINADO
... A37: 45442 | B37: VCU986 | C37: TORO AUTOS S.A.S. | D37: 800007748 | E37: AVENIDA VASQUEZ COBO # 25N-68 | F37: RAMON EMILIO QUINTERO | G37: 6370612 | I37: 202441520100029082 | J37: 45394 | K37: 4152.010.21.0.0600 | L37: 45432 | M37: No se concede | N37: PAOLA ANDREA MATAMOROS | O37: NINGUNA | P37: EMPRESA | Q37: PROCESO TERMINADO
A38: 45442 | B38: VCH997 | C38: EMPRESA DE TRANSPORTES CAÑAVERAL S.A. | D38: 800109341 | F38: FRAN LEONARDO HERRERA ORTIZ | G38: 94520071 | H38: CRA 4 No. 13-25 oficina 801 | I38: 202441520100039352 | J38: 45421 | K38: 4152.010.21.0.1058 | L38: 45491 | M38: No se concede | N38: PAOLA ANDREA MATAMOROS | O38: NINGUNA | P38: PROPIETARIO | Q38: PROCESO TERMINADO
A39: 45442 | B39: WMX018 | C39: TORO AUTOS S.A.S. | D39: 800007748 | E39: AVENIDA VASQUEZ COBO # 25N-68 | F39: JAIR CARMONA ARANGO | G39: 18413749 | I39: 202441520100029082 | J39: 45394 | K39: 4152.010.21.0.0761 | L39: 45442 | M39: No se concede | N39: PAOLA ANDREA MATAMOROS | O39: NINGUNA | P39: EMPRESA | Q39: PROCESO TERMINADO
A40: 45442 | B40: VCW622 | C40: TORO AUTOS S.A.S. | D40: 800007748 | E40: AVENIDA VASQUEZ COBO # 25N-68 | F40: OSCAR MAURICIO ESCARRIA VILLEGAS | G40: 16776045 | H40: CRA 46 No. 56 E 55 | I40: 202441520100029082 | J40: 45394 | K40: 4152.010.21.0.0760 | L40: 45442 | M40: No se concede | N40: PAOLA ANDREA MATAMOROS | O40: NINGUNA | P40: EMPRESA | Q40: PROCESO TERMINADO
A41: 45442 | B41: VCW812 | C41: TORO AUTOS S.A.S. | D41: 800007748 | E41: AVENIDA VASQUEZ COBO # 25N-68 | F41: OSCAR MAURICIO ESCARRIA VILLEGAS | G41: 16776045 | I41: 202441520100029082 | J41: 45394 | K41: 4152.010.21.0.0759 | L41: 45442 | M41: No se concede | N41: PAOLA ANDREA MATAMOROS | O41: NINGUNA | P41: EMPRESA | Q41: PROCESO TERMINADO
A42: 45442 | B42: VCW625 | C42: TORO AUTOS S.A.S. | D42: 800007748 | E42: AVENIDA VASQUEZ COBO # 25N-68 | F42: OSCAR MAURICIO ESCARRIA VILLEGAS | G42: 16776045 | I42: 202441520100029082 | J42: 45394 | K42: 4152.010.21.0.0758 | L42: 45442 | M42: No se concede | N42: PAOLA ANDREA MATAMOROS | O42: NINGUNA | P42: EMPRESA | Q42: PROCESO TERMINADO
A43: 45442 | B43: VCG387 | C43: TORO AUTOS S.A.S. | D43: 800007748 | E43: AVENIDA VASQUEZ COBO # 25N-68 | F43: LUIS ENRIQUE MORALES YILMA MORALES GARCIA | G43: 16749920 31992006 | I43: 202441520100029082 | J43: 45394 | K43: 4152.010.21.0.0757 | L43: 45442 | M43: No se concede | N43: PAOLA ANDREA MATAMOROS | O43: NINGUNA | P43: EMPRESA | Q43: PROCESO TERMINADO
A44: 45442 | B44: VCK566 | C44: TORO AUTOS S.A.S. | D44: 800007748 | E44: AVENIDA VASQUEZ COBO # 25N-68 | F44: JORGE ELIECER FAJARDO MANCERA | G44: 14440457 | I44: 202441520100029082 | J44: 45394 | K44: 4152.010.21.0.0764 | L44: 45442 | M44: No se concede | N44: PAOLA ANDREA MATAMOROS | O44: NINGUNA | P44: EMPRESA | Q44: PROCESO TERMINADO
...

Sheet DATOS
A1: EMPRESA | B1: NIT | C1: DIRECCIÓN | D1: FUNCIONARIOS | E1: SOLICITANTE | F1: ESTADO | G1: OBSERVACIÓN
A2: AUTOS Y TAXIS MORALES GOMEZ Y CIA LTDA. | B2: 805027885 | D2: ALVARO HERNAN LOSADA | E2: EMPRESA | F2: REQUERIMIENTO A SOLICITANTE | G2: No se concede
A3: BLANCO Y NEGRO MASIVO S.A. | B3: 900007044 | C3: AVENIDA VASQUEZ COBO # 23N-59 | D3: ARCHIVO GESTIÓN DOCUMENTAL | E3: PROPIETARIO | F3: TRASLADO A EMPRESA | G3: Si se concede
A4: CIA TRANSPORTADORA VERDE BRETAÑA S,A. | B4: 890300483 | C4: CALLE 51 # 41D-33 | D4: DIEGO TRUJILLO | E4: MUTUO ACUERDO | F4: TRASLADO A PROPIETARIO | G4: En estudio
A5: COOPERATIVA DE TRANSPORTADORES CALIPUERTO LTDA. | B5: 890310476 | C5: CALLE 31 # 12-27 BENJAMIN HERRERA | D5: GESTIÓN DOCUMENTAL | F5: PROYECCIÓN DE RESOLUCIÓN | G5: Desistimiento Tacito
A6: COOPERATIVA DE TRANSPORTADORES SOLIDARIOS | B6: 800150374 | C6: CARRERA 70 # 1-36 OESTE | D6: GUSTAVO RAMIREZ CASAÑAS | F6: NOTIFICACIÓN DE RESOLUCIÓN | G6: RECURSO- SE REPONE
A7: COOPERATIVA DE TRANSPORTADORES UNIDOS COOTRANSUNIDOS | B7: 805005911 | C7: CALLE 1 OESTE # 52-01 | D7: JAVIER MEDINA HERRERA | F7: TRASLADO A REGISTRO AUTOMOTOR | G7: RECURSO- NO SE REPONE
A8: COOPERATIVA DE TRANSPORTE MIXTO DE CAMPEROS | B8: 900298380 | D8: JOHN JAIRO MONTOYA R. | F8: PROCESO TERMINADO
A9: COOPERATIVA ESPECIALIZADA DE TRANSPORTE Y SERVICIOS LA ERMITA LTDA. | B9: 890303525 | C9: CALLE 31 # 2BN-106 | D9: JOSE CARLOS ORTEGÓN | F9: RESPUESTA
A10: COOPERATIVA ESPECIALIZADA DE TRANSPORTES COOMOEPAL | B10: 890303081 | C10: CALLE 5 # 61-89 LOCAL 8 CC CAÑAVERALEJO | D10: JOSUA GIL | F10: EN ESTUDIO
A11: COOPERATIVA INTEGRAL DE TRANSPORTADORES TAXIS EL TRIUNFO | B11: 890304705 | C11: CARRERA 44 # 15-57 | D11: LEONARDO MOLINA | F11: NOTIFICACION DE RESPUESTA
A12: COOPERATIVA INTEGRAL DE TRANSPORTADORES TROPICANA LTDA. | B12: 890303967 | C12: CARRERA 33 # 14-05 | D12: LUIS FERNANDO GIL R. | F12: NOTIFICACION RECURSO
A13: COOPERATIVA INTEGRAL DE TRANSPORTES FLORIDA CALI LTDA. | B13: 890302797 | C13: CALLE 30 # 2BN-42 LOCAL 625 | D13: PAOLA ANDREA MATAMOROS | F13: EN VoBo Y FIRMA DESPACHO
A14: COOPERATIVA MULTIACTIVA AL SERVICIO DE LA INDUSTRIA DEL TRANSPORTE EN AMERICA COOPAMER | B14: SUPERINTENDENCIA | D14: ROCIÓ RAMIREZ ACOSTA | F14: MEDIDAS CAUTELARES
A15: COOPERATIVA MULTIACTIVA DE LOS TAXISTAS DEL AEROPUERTO DE PALMASECA LTDA COOPTAXPAL | B15: 890320646 | D15: SANDRA TRIANA
A16: COOPERATIVA MULTIACTIVA DE TRANSPORTADORES SINDIUNION LTDA. | B16: 800084136 | C16: TRANSVERSAL 25 # 23-16 | D16: YADIRA TAVERA
A17: COSMOTAXIS S.A.S. SOCIEDAD POR ACCIONES SIMPLIFICADA | B17: 900783557 | D17: YEANA ESPAÑA
A18: EL MUNDO DE LOS TAXIS LTDA. | B18: 805029930 | C18: CALLE 25 N # 2 DN-07 | D18: LAURA CARVAJAL
A19: EMP. ESPECIALES GYG S.A.S | B19: SUPERINTENDENCIA | D19: ISABEL HERRERA QUINTERO
A20: EMPRESA DE TRANSPORTADORES UNION DE TAXISTAS S.A. | B20: 891901074 | C20: CALLE 5A # 23-08 | D20: DAVID PANESSO
A21: EMPRESA DE TRANSPORTE MASIVO ETM S.A. | B21: 900100778 | C21: AVENIDA VASQUEZ COBO # 23N-59 | D21: ANGIE CRISTINA JARA VIAFARA
A22: EMPRESA DE TRANSPORTE RIO CALI S.A. | B22: 800125299 | C22: CALLE 36 # 10-451 ACOPI-YUMBO | D22: WILMER BURBANO
A23: EMPRESA DE TRANSPORTES AMARILLO LIMITADA | B23: 900078188 | C23: CARRERA 50 # 14A-79 | D23: LUCIA GUINETH BELTRÁN HUERTAS
A24: EMPRESA DE TRANSPORTES CAÑAVERAL S.A. | B24: 800109341 | D24: DARLY BANESSA SUAREZ CARMONA
A25: EMPRESA DE TRANSPORTES DE TAXIS SINTRANSPUBLIC S.A. | B25: 890306749 | C25: CALLE 5A # 22-36 | D25: MARIA CAMILA CASTAÑEDA
A26: EMPRESA DE TRANSPORTES SANTIAGO DE CALI ALAMEDA S.A. | B26: 890301295 | C26: CARRERA 70 # 1-71 | D26: BLANCA LILIANA CHAVEZ PANTOJA
A27: EMPRESA DE TRANSPORTES SULTANA DEL VALLE S.A.S. | B27: 890301296
A28: EMPRESA DE TRANSPORTES VILLANUEVA BELEN LIMITADA | B28: 890301786 | C28: CARRERA 29 # 46A -50
A29: GRUPO INTEGRADO DE TRANSPORTA MASIVO S.A. | B29: 900099310 | C29: AVENIDA VASQUEZ COBO # 23N-59
A30: J@J REPRESENTACIONES LTDA. | B30: 805027566
A31: LINEAS CALIFORNIA SOCIEDAD POR ACCIONES SIMPLIFICADA | B31: 900178594 | C31: CALLE 70 # 7B-03
A32: RADIO TAXI AEROPUERTO S.A. | B32: 860531135 | C32: CALLE 52 # 1B-160
A33: RADIO TAXI FUNDADORES S.A. | B33: 900074269 | C33: TRANSVERSAL 25 # 23-16
A34: SERVINTEGRADOS DEL VALLE | B34: 900147633
A35: SETRANS S.A | B35: SUPERINTENDENCIA
A36: T. ESPECIALES EVEREST | B36: SUPERINTENDENCIA
A37: TAX EMPERADOR S.A.S. | B37: 890307467 | C37: CARRERA 70 # 1-36 OESTE
A38: TAX EXPRESS CALI S.A.S. | B38: 900841089 | C38: CALLE 13 # 32-81
A39: TAX RIOS S.A. | B39: 890301026 | C39: CALLE 13 # 32-81
A40: TAXIS DE ORIENTE S.A. | B40: 900189781
...
